<?xml version="1.0" ?>
<robot name="everyday_robot">
    <link name="mobile_base">
        <inertial>
            <origin rpy="0 0 0" xyz="0 0 0"/>
            <mass value="10.0"/>
            <inertia ixx="1" ixy="0" ixz="0" iyy="1" iyz="0" izz="1"/>
        </inertial>
        <visual>
            <origin rpy="0 0 0" xyz="0 0 0"/>
            <geometry>
                <mesh filename="../meshes/mobile_base.obj"/>
            </geometry>
            <material name="white">
                <color rgba="1 1 1 1"/>
            </material>
        </visual>
        <collision>
            <origin rpy="0 0 0" xyz="0 0 0"/>
            <geometry>
                <mesh filename="../meshes/mobile_base.obj"/>
            </geometry>
        </collision>
    </link>
    <joint name="left_front_wheel_joint" type="continuous">
        <parent link="mobile_base"/>
        <child link="left_front_wheel"/>
        <origin rpy="0 0 0" xyz="0.12 0.155 0.05"/>
        <axis xyz="0 1 0"/>
    </joint>
    <link name="left_front_wheel">
        <inertial>
            <origin rpy="1.570796 0 0" xyz="0 0 0"/>
            <mass value="2"/>
            <inertia ixx="1" ixy="0" ixz="0" iyy="1" iyz="0" izz="1"/>
        </inertial>
        <visual>
            <origin rpy="1.570796 0 0" xyz="0 0 0"/>
            <geometry>
                <cylinder radius="0.05" length="0.02"/>
            </geometry>
            <material name="black">
                <color rgba="0 0 0 1"/>
            </material>
        </visual>
        <collision>
            <origin rpy="1.570796 0 0" xyz="0 0 0"/>
            <geometry>
                <cylinder radius="0.05" length="0.02"/>
            </geometry>
        </collision>
    </link>
    <joint name="right_front_wheel_joint" type="continuous">
        <parent link="mobile_base"/>
        <child link="right_front_wheel"/>
        <origin rpy="0 0 0" xyz="0.12 -0.15 0.05"/>
        <axis xyz="0 1 0"/>
    </joint>
    <link name="right_front_wheel">
        <inertial>
            <origin rpy="1.570796 0 0" xyz="0 0 0"/>
            <mass value="2"/>
            <inertia ixx="1" ixy="0" ixz="0" iyy="1" iyz="0" izz="1"/>
        </inertial>
        <visual>
            <origin rpy="1.570796 0 0" xyz="0 0 0"/>
            <geometry>
                <cylinder radius="0.05" length="0.02"/>
            </geometry>
            <material name="black">
                <color rgba="0 0 0 1"/>
            </material>
        </visual>
        <collision>
            <origin rpy="1.570796 0 0" xyz="0 0 0"/>
            <geometry>
                <cylinder radius="0.05" length="0.02"/>
            </geometry>
        </collision>
    </link>
    <joint name="left_behind_wheel_joint" type="continuous">
        <parent link="mobile_base"/>
        <child link="left_behind_wheel"/>
        <origin rpy="0 0 0" xyz="-0.15 0.12 0.03"/>
        <axis xyz="0 1 0"/>
    </joint>
    <link name="left_behind_wheel">
        <inertial>
            <origin rpy="1.570796 0 0" xyz="0 0 0"/>
            <mass value="10"/>
            <inertia ixx="1" ixy="0" ixz="0" iyy="1" iyz="0" izz="1"/>
        </inertial>
        <visual>
            <origin rpy="1.570796 0 0" xyz="0 0 0"/>
            <geometry>
                <cylinder radius="0.03" length="0.02"/>
            </geometry>
            <material name="black">
                <color rgba="0 0 0 1"/>
            </material>
        </visual>
        <collision>
            <origin rpy="1.570796 0 0" xyz="0 0 0"/>
            <geometry>
                <cylinder radius="0.03" length="0.02"/>
            </geometry>
        </collision>
    </link>
    <joint name="right_behind_wheel_joint" type="continuous">
        <parent link="mobile_base"/>
        <child link="right_behind_wheel"/>
        <origin rpy="0 0 0" xyz="-0.15 -0.12 0.03"/>
        <axis xyz="0 1 0"/>
    </joint>
    <link name="right_behind_wheel">
        <inertial>
            <origin rpy="1.570796 0 0" xyz="0 0 0"/>
            <mass value="10"/>
            <inertia ixx="1" ixy="0" ixz="0" iyy="1" iyz="0" izz="1"/>
        </inertial>
        <visual>
            <origin rpy="1.570796 0 0" xyz="0 0 0"/>
            <geometry>
                <cylinder radius="0.03" length="0.02"/>
            </geometry>
            <material name="black">
                <color rgba="0 0 0 1"/>
            </material>
        </visual>
        <collision>
            <origin rpy="1.570796 0 0" xyz="0 0 0"/>
            <geometry>
                <cylinder radius="0.03" length="0.02"/>
            </geometry>
        </collision>
    </link>
    <joint name="body_base_joint" type="fixed">
        <parent link="mobile_base"/>
        <child link="body_base"/>
        <origin rpy="0 0 0" xyz="0.12 0 0.256"/>
        <axis xyz="0 0 1"/>
    </joint>
    <link name="body_base">
        <inertial>
            <origin rpy="0 0 0" xyz="0 0 0"/>
            <mass value="0.2"/>
            <inertia ixx="1" ixy="0" ixz="0" iyy="1" iyz="0" izz="1"/>
        </inertial>
        <visual>
            <origin rpy="0 0 0" xyz="0 0 0"/>
            <geometry>
                <mesh filename="../meshes/body_base.obj"/>
            </geometry>
            <material name="white">
                <color rgba="1 1 1 1"/>
            </material>
        </visual>
        <collision>
            <origin rpy="0 0 0" xyz="0 0 0"/>
            <geometry>
                <mesh filename="../meshes/body_base.obj"/>
            </geometry>
        </collision>
    </link>
    <joint name="body_link1_joint" type="fixed">
        <parent link="body_base"/>
        <child link="body_link1"/>
        <origin rpy="0 0 0" xyz="0 0 0.129"/>
        <axis xyz="0 0 1"/>
    </joint>
    <link name="body_link1">
        <inertial>
            <origin rpy="0 0 0" xyz="0 0 0"/>
            <mass value="3"/>
            <inertia ixx="1" ixy="0" ixz="0" iyy="1" iyz="0" izz="1"/>
        </inertial>
        <visual>
            <origin rpy="0 0 0" xyz="0 0 0"/>
            <geometry>
                <mesh filename="../meshes/body_link1.obj"/>
            </geometry>
            <material name="white">
                <color rgba="1 1 1 1"/>
            </material>
        </visual>
        <collision>
            <origin rpy="0 0 0" xyz="0 0 0"/>
            <geometry>
                <mesh filename="../meshes/body_link1.obj"/>
            </geometry>
        </collision>
    </link>
    <joint name="arm_link1_joint" type="revolute">
        <parent link="body_link1"/>
        <child link="arm_link1"/>
        <origin rpy="0 0 0" xyz="0 0 0.165"/>
        <axis xyz="0 0 1"/>
        <limit effort="150.0" lower="-6.28318530718" upper="6.28318530718" velocity="3.15"/>
    </joint>
    <link name="arm_link1">
        <inertial>
            <origin rpy="0 0 0" xyz="0 -0.0208 0"/>
            <mass value="3"/>
            <inertia ixx="1" ixy="0" ixz="0" iyy="1" iyz="0" izz="1"/>
        </inertial>
        <visual>
            <origin rpy="0 0 0" xyz="0 -0.0208 0"/>
            <geometry>
                <mesh filename="../meshes/arm_link1.obj"/>
            </geometry>
            <material name="white">
                <color rgba="1 1 1 1"/>
            </material>
        </visual>
        <collision>
            <origin rpy="0 0 0" xyz="0 -0.0208 0"/>
            <geometry>
                <mesh filename="../meshes/arm_link1.obj"/>
            </geometry>
        </collision>
    </link>
    <joint name="arm_link2_joint" type="revolute">
        <parent link="arm_link1"/>
        <child link="arm_link2"/>
        <origin rpy="0 0 0" xyz="0 -0.0692 0"/>
        <axis xyz="0 1 0"/>
        <limit effort="150.0" lower="-6.28318530718" upper="6.28318530718" velocity="3.15"/>
    </joint>
    <link name="arm_link2">
        <inertial>
            <origin rpy="0 0 0" xyz="0 0 -0.021"/>
            <mass value="3"/>
            <inertia ixx="1" ixy="0" ixz="0" iyy="1" iyz="0" izz="1"/>
        </inertial>
        <visual>
            <origin rpy="0 0 0" xyz="0 0 -0.021"/>
            <geometry>
                <mesh filename="../meshes/arm_link2.obj"/>
            </geometry>
            <material name="white">
                <color rgba="1 1 1 1"/>
            </material>
        </visual>
        <collision>
            <origin rpy="0 0 0" xyz="0 0 -0.021"/>
            <geometry>
                <mesh filename="../meshes/arm_link2.obj"/>
            </geometry>
        </collision>
    </link>
    <joint name="arm_link3_joint" type="revolute">
        <parent link="arm_link2"/>
        <child link="arm_link3"/>
        <origin rpy="0 0 0" xyz="0 -0.0108 -0.218"/>
        <axis xyz="0 0 1"/>
        <limit effort="150.0" lower="-6.28318530718" upper="6.28318530718" velocity="3.15"/>
    </joint>
    <link name="arm_link3">
        <inertial>
            <origin rpy="0 0 0" xyz="-0.011 0 0"/>
            <mass value="3"/>
            <inertia ixx="1" ixy="0" ixz="0" iyy="1" iyz="0" izz="1"/>
        </inertial>
        <visual>
            <origin rpy="0 0 0" xyz="-0.011 0 0"/>
            <geometry>
                <mesh filename="../meshes/arm_link3.obj"/>
            </geometry>
            <material name="white">
                <color rgba="1 1 1 1"/>
            </material>
        </visual>
        <collision>
            <origin rpy="0 0 0" xyz="-0.011 0 0"/>
            <geometry>
                <mesh filename="../meshes/arm_link3.obj"/>
            </geometry>
        </collision>
    </link>
    <joint name="arm_link4_joint" type="revolute">
        <parent link="arm_link3"/>
        <child link="arm_link4"/>
        <origin rpy="0 0 0" xyz="-0.075 0 -0.021"/>
        <axis xyz="1 0 0"/>
        <limit effort="150.0" lower="-6.28318530718" upper="6.28318530718" velocity="3.15"/>
    </joint>
    <link name="arm_link4">
        <inertial>
            <origin rpy="0 0 0" xyz="0 0 0.013"/>
            <mass value="1"/>
            <inertia ixx="1" ixy="0" ixz="0" iyy="1" iyz="0" izz="1"/>
        </inertial>
        <visual>
            <origin rpy="0 0 0" xyz="0 0 0.013"/>
            <geometry>
                <mesh filename="../meshes/arm_link4.obj"/>
            </geometry>
            <material name="white">
                <color rgba="1 1 1 1"/>
            </material>
        </visual>
        <collision>
            <origin rpy="0 0 0" xyz="0 0 0.013"/>
            <geometry>
                <mesh filename="../meshes/arm_link4.obj"/>
            </geometry>
        </collision>
    </link>
    <joint name="arm_link5_joint" type="revolute">
        <parent link="arm_link4"/>
        <child link="arm_link5"/>
        <origin rpy="0 0 0" xyz="-0.0148 0 0.14"/>
        <axis xyz="0 0 1"/>
        <limit effort="150.0" lower="-6.28318530718" upper="6.28318530718" velocity="3.15"/>
    </joint>
    <link name="arm_link5">
        <inertial>
            <origin rpy="0 0 0" xyz="-0.0052 0 0"/>
            <mass value="1"/>
            <inertia ixx="1" ixy="0" ixz="0" iyy="1" iyz="0" izz="1"/>
        </inertial>
        <visual>
            <origin rpy="0 0 0" xyz="-0.0052 0 0"/>
            <geometry>
                <mesh filename="../meshes/arm_link5.obj"/>
            </geometry>
            <material name="white">
                <color rgba="1 1 1 1"/>
            </material>
        </visual>
        <collision>
            <origin rpy="0 0 0" xyz="-0.0052 0 0"/>
            <geometry>
                <mesh filename="../meshes/arm_link5.obj"/>
            </geometry>
        </collision>
    </link>
    <joint name="arm_link6_joint" type="revolute">
        <parent link="arm_link5"/>
        <child link="arm_link6"/>
        <origin rpy="0 0 0" xyz="0.0145 0 0.0693"/>
        <axis xyz="1 0 0"/>
        <limit effort="150.0" lower="-6.28318530718" upper="6.28318530718" velocity="3.15"/>
    </joint>
    <link name="arm_link6">
        <inertial>
            <origin rpy="0 0 0" xyz="0 0 0.03"/>
            <mass value="1"/>
            <inertia ixx="1" ixy="0" ixz="0" iyy="1" iyz="0" izz="1"/>
        </inertial>
        <visual>
            <origin rpy="0 0 0" xyz="0 0 0.03"/>
            <geometry>
                <mesh filename="../meshes/arm_link6.obj"/>
            </geometry>
            <material name="white">
                <color rgba="1 1 1 1"/>
            </material>
        </visual>
        <collision>
            <origin rpy="0 0 0" xyz="0 0 0.03"/>
            <geometry>
                <mesh filename="../meshes/arm_link6.obj"/>
            </geometry>
        </collision>
    </link>
    <joint name="body_link2_joint" type="fixed">
        <parent link="body_link1"/>
        <child link="body_link2"/>
        <origin rpy="0 0 0" xyz="0 0 0.307"/>
        <axis xyz="0 0 1"/>
    </joint>
    <link name="body_link2">
        <inertial>
            <origin rpy="0 0 0" xyz="0.006 0 0"/>
            <mass value="3"/>
            <inertia ixx="1" ixy="0" ixz="0" iyy="1" iyz="0" izz="1"/>
        </inertial>
        <visual>
            <origin rpy="0 0 0" xyz="0.006 0 0"/>
            <geometry>
                <mesh filename="../meshes/body_link2.obj"/>
            </geometry>
            <material name="white">
                <color rgba="1 1 1 1"/>
            </material>
        </visual>
        <collision>
            <origin rpy="0 0 0" xyz="0.006 0 0"/>
            <geometry>
                <mesh filename="../meshes/body_link2.obj"/>
            </geometry>
        </collision>
    </link>
    <joint name="head_link1_joint" type="revolute">
        <parent link="body_link2"/>
        <child link="head_link1"/>
        <origin rpy="0 0 0" xyz="0 0 0.117"/>
        <axis xyz="0 0 1"/>
        <limit effort="150.0" lower="-6.28318530718" upper="6.28318530718" velocity="3.15"/>
    </joint>
    <link name="head_link1">
        <inertial>
            <origin rpy="0 0 0" xyz="0.01 0 0"/>
            <mass value="0.7"/>
            <inertia ixx="1" ixy="0" ixz="0" iyy="1" iyz="0" izz="1"/>
        </inertial>
        <visual>
            <origin rpy="0 0 0" xyz="0.01 0 0"/>
            <geometry>
                <mesh filename="../meshes/head_link1.obj"/>
            </geometry>
            <material name="white">
                <color rgba="1 1 1 1"/>
            </material>
        </visual>
        <collision>
            <origin rpy="0 0 0" xyz="0.01 0 0"/>
            <geometry>
                <mesh filename="../meshes/head_link1.obj"/>
            </geometry>
        </collision>
    </link>
    <joint name="head_link2_joint" type="revolute">
        <parent link="head_link1"/>
        <child link="head_link2"/>
        <origin rpy="0 0 0" xyz="0.04 0 0.016"/>
        <axis xyz="0 1 0"/>
        <limit effort="50.0" lower="0.7854" upper="0.7854" velocity="0.7854"/>
    </joint>
    <link name="head_link2">
        <inertial>
            <origin rpy="0 0 0" xyz="0.025 0 0"/>
            <mass value="0.3"/>
            <inertia ixx="1" ixy="0" ixz="0" iyy="1" iyz="0" izz="1"/>
        </inertial>
        <visual>
            <origin rpy="0 0 0" xyz="0.025 0 0"/>
            <geometry>
                <mesh filename="../meshes/head_link2.obj"/>
            </geometry>
            <material name="white">
                <color rgba="1 1 1 1"/>
            </material>
        </visual>
        <collision>
            <origin rpy="0 0 0" xyz="0.025 0 0"/>
            <geometry>
                <mesh filename="../meshes/head_link2.obj"/>
            </geometry>
        </collision>
    </link>
    <joint name="lidar_joint" type="revolute">
        <parent link="body_link2"/>
        <child link="lidar"/>
        <origin rpy="0 0.2618 0" xyz="0.035 0 0.01"/>
        <axis xyz="0 0 1"/>
        <limit effort="150.0" lower="-6.28318530718" upper="6.28318530718" velocity="3.15"/>
    </joint>
    <link name="lidar">
        <inertial>
            <origin rpy="0 0 0" xyz="0 0 0"/>
            <mass value="0.1"/>
            <inertia ixx="1" ixy="0" ixz="0" iyy="1" iyz="0" izz="1"/>
        </inertial>
        <visual>
            <origin rpy="0 0 0" xyz="0 0 0"/>
            <geometry>
                <mesh filename="../meshes/lidar.obj"/>
            </geometry>
            <material name="white">
                <color rgba="1 1 1 1"/>
            </material>
        </visual>
        <collision>
            <origin rpy="0 0 0" xyz="0 0 0"/>
            <geometry>
                <mesh filename="../meshes/lidar.obj"/>
            </geometry>
        </collision>
    </link>
</robot>